Workbook

Sheet Portaria
E5: SISTEMA DE CONSULTA DE ACESSO - PORTARIA (BOUGAINVILLE)
E7: DIGITE O LOTE-QUADRA
J9: 7-55
E13: STATUS DE ACESSO
E14: =IF(J9=(IFERROR(VLOOKUP(J9,'Lote Entregues'!J6:J4500,1,FALSE),"OK")), "EMBARGADO", "LIBERADO") -> LIBERADO
E16: =IF(IFERROR(VLOOKUP(J9,'Lote Entregues'!C6:G4500,5,FALSE), "NÃO")= "SIM", "MORADOR", "NÃO É MORADOR") -> NÃO É MORADOR

Sheet Lote Entregues
B3: ATUALIZADO - 22/10/2026
B4: LISTA DE LOTES ENTREGUES - BOUGAINVILLLE
B5: QUANTIDADES ENTREGUES | C5: LOTE - QUADRA | D5: LOTE | E5: QUADRA | F5: PROPRIETÁRIO | G5: MORADOR | H5: DATA DA ENTREGA | I5: SETOR | J5: ANALISE | K5: SITUAÇÃO
B6: 1 | C6: 19-76 | D6: 19 | E6: 76 | F6: A ENGENHARIA DO FRIO EIRELI | H6: 46030 | I6: ROXO | J6: =IFERROR(VLOOKUP($C6,Embargos!$E$4:$E$3878,1,FALSE), "OK") -> OK | K6: =IF(J6=C6, "EMBARGADO", "LIBERADO") -> LIBERADO
B7: 2 | C7: 7-26 | D7: 7 | E7: 26 | F7: ADAILSON OLIVEIRA DA SILVA | H7: 44960 | I7: VERMELHO | J7: =IFERROR(VLOOKUP($C7,Embargos!$E$4:$E$3878,1,FALSE), "OK") -> OK | K7: =IF(J7=C7, "EMBARGADO", "LIBERADO") -> LIBERADO
B8: 3 | C8: 46-69 | D8: 46 | E8: 69 | F8: ADAILSON SILVA DOS SANTOS | H8: 44944 | I8: AMARELO | J8: =IFERROR(VLOOKUP($C8,Embargos!$E$4:$E$3878,1,FALSE), "OK") -> OK | K8: =IF(J8=C8, "EMBARGADO", "LIBERADO") -> LIBERADO
B9: 4 | C9: 1-52 | D9: 1 | E9: 52 | F9: ADALBERTO PAIVA SILVA FILHO | H9: 44942 | I9: AMARELO | J9: =IFERROR(VLOOKUP($C9,Embargos!$E$4:$E$3878,1,FALSE), "OK") -> OK | K9: =IF(J9=C9, "EMBARGADO", "LIBERADO") -> LIBERADO
B10: 5 | C10: 30-19 | D10: 30 | E10: 19 | F10: ADAM TAVARES MAGALHAES | H10: 46175 | I10: EXCLUSIVE | J10: =IFERROR(VLOOKUP($C10,Embargos!$E$4:$E$3878,1,FALSE), "OK") -> OK | K10: =IF(J10=C10, "EMBARGADO", "LIBERADO") -> LIBERADO
B11: 6 | C11: 29-24 | D11: 29 | E11: 24 | F11: ADAM TAVARES MAGALHAES | H11: 46175 | I11: VERMELHO | J11: =IFERROR(VLOOKUP($C11,Embargos!$E$4:$E$3878,1,FALSE), "OK") -> 29-24 | K11: =IF(J11=C11, "EMBARGADO", "LIBERADO") -> EMBARGADO
B12: 7 | C12: 8-19 | D12: 8 | E12: 19 | F12: ADAM TAVARES MAGALHAES | H12: 46175 | I12: EXCLUSIVE | J12: =IFERROR(VLOOKUP($C12,Embargos!$E$4:$E$3878,1,FALSE), "OK") -> 8-19 | K12: =IF(J12=C12, "EMBARGADO", "LIBERADO") -> EMBARGADO
B13: 8 | C13: 8-46 | D13: 8 | E13: 46 | F13: ADELE SUZANA DO CARMO TAVARES | H13: 46265 | I13: LARANJA | J13: =IFERROR(VLOOKUP($C13,Embargos!$E$4:$E$3878,1,FALSE), "OK") -> OK | K13: =IF(J13=C13, "EMBARGADO", "LIBERADO") -> LIBERADO
B14: 9 | C14: 33-14 | D14: 33 | E14: 14 | F14: ADEMIR GONCALVES CORREA JUNIOR | H14: 45262 | I14: GARDEN | J14: =IFERROR(VLOOKUP($C14,Embargos!$E$4:$E$3878,1,FALSE), "OK") -> OK | K14: =IF(J14=C14, "EMBARGADO", "LIBERADO") -> LIBERADO
B15: 10 | C15: 34-14 | D15: 34 | E15: 14 | F15: ADEMIR GONCALVES CORREA JUNIOR | H15: 45262 | I15: GARDEN | J15: =IFERROR(VLOOKUP($C15,Embargos!$E$4:$E$3878,1,FALSE), "OK") -> OK | K15: =IF(J15=C15, "EMBARGADO", "LIBERADO") -> LIBERADO
B16: 11 | C16: 24-16 | D16: 24 | E16: 16 | F16: ADENARD FRANCISCO CLEOPHAS CUNHA | H16: 46165 | I16: LARANJA | J16: =IFERROR(VLOOKUP($C16,Embargos!$E$4:$E$3878,1,FALSE), "OK") -> OK | K16: =IF(J16=C16, "EMBARGADO", "LIBERADO") -> LIBERADO
B17: 12 | C17: 18-29 | D17: 18 | E17: 29 | F17: ADERSON PESSOA BARRETO | H17: 44965 | I17: VERMELHO | J17: =IFERROR(VLOOKUP($C17,Embargos!$E$4:$E$3878,1,FALSE), "OK") -> OK | K17: =IF(J17=C17, "EMBARGADO", "LIBERADO") -> LIBERADO
B18: 13 | C18: 20-67 | D18: 20 | E18: 67 | F18: ADILSON OLIVEIRA COSTA JUNIOR | H18: 44952 | I18: AMARELO | J18: =IFERROR(VLOOKUP($C18,Embargos!$E$4:$E$3878,1,FALSE), "OK") -> OK | K18: =IF(J18=C18, "EMBARGADO", "LIBERADO") -> LIBERADO
... B44: 39 | C44: 27-19 | D44: 27 | E44: 19 | F44: ALAN MESSIAS MOTA DE OLIVEIRA | H44: 45350 | I44: EXCLUSIVE | J44: =IFERROR(VLOOKUP($C44,Embargos!$E$4:$E$3878,1,FALSE), "OK") -> OK | K44: =IF(J44=C44, "EMBARGADO", "LIBERADO") -> LIBERADO
B45: 40 | C45: 37-6 | D45: 37 | E45: 6 | F45: ALAN MORAES VIANA | H45: 46181 | I45: VERMELHO | J45: =IFERROR(VLOOKUP($C45,Embargos!$E$4:$E$3878,1,FALSE), "OK") -> 37-6 | K45: LIBERADO
B46: 41 | C46: 7-42 | D46: 7 | E46: 42 | F46: ALAN RODRIGO BRITO FARIAS | H46: 45849 | I46: EXCLUSIVE | J46: =IFERROR(VLOOKUP($C46,Embargos!$E$4:$E$3878,1,FALSE), "OK") -> OK | K46: =IF(J46=C46, "EMBARGADO", "LIBERADO") -> LIBERADO
B47: 42 | C47: 32-55 | D47: 32 | E47: 55 | F47: ALAN SILVA DOS SANTOS | H47: 45930 | I47: AMARELO | J47: =IFERROR(VLOOKUP($C47,Embargos!$E$4:$E$3878,1,FALSE), "OK") -> OK | K47: =IF(J47=C47, "EMBARGADO", "LIBERADO") -> LIBERADO
B48: 43 | C48: 23-54 | D48: 23 | E48: 54 | F48: ALANA FLAVIA PINHEIRO BAHIA | H48: 46034 | I48: AMARELO | J48: =IFERROR(VLOOKUP($C48,Embargos!$E$4:$E$3878,1,FALSE), "OK") -> OK | K48: =IF(J48=C48, "EMBARGADO", "LIBERADO") -> LIBERADO
B49: 44 | C49: 3-33 | D49: 3 | E49: 33 | F49: ALBERTO CARLOS GALHARDO XAVIER | H49: 44994 | I49: VERMELHO | J49: =IFERROR(VLOOKUP($C49,Embargos!$E$4:$E$3878,1,FALSE), "OK") -> OK | K49: =IF(J49=C49, "EMBARGADO", "LIBERADO") -> LIBERADO
B50: 45 | C50: 8-3 | D50: 8 | E50: 3 | F50: ALBERTO CARLOS GALHARDO XAVIER | H50: 45749 | I50: GARDEN | J50: =IFERROR(VLOOKUP($C50,Embargos!$E$4:$E$3878,1,FALSE), "OK") -> OK | K50: =IF(J50=C50, "EMBARGADO", "LIBERADO") -> LIBERADO
B51: 46 | C51: 9-3 | D51: 9 | E51: 3 | F51: ALBERTO CARLOS GALHARDO XAVIER | H51: 45749 | I51: GARDEN | J51: =IFERROR(VLOOKUP($C51,Embargos!$E$4:$E$3878,1,FALSE), "OK") -> OK | K51: =IF(J51=C51, "EMBARGADO", "LIBERADO") -> LIBERADO
B52: 47 | C52: 52-34 | D52: 52 | E52: 34 | F52: ALBERTO CEZAR PEREIRA SILVA | H52: 44953 | I52: VERMELHO | J52: =IFERROR(VLOOKUP($C52,Embargos!$E$4:$E$3878,1,FALSE), "OK") -> 52-34 | K52: =IF(J52=C52, "EMBARGADO", "LIBERADO") -> EMBARGADO
B53: 48 | C53: 35-51 | D53: 35 | E53: 51 | F53: ALBERTO OLIVEIRA BARBOSA JUNIOR | H53: 44950 | I53: AMARELO | J53: =IFERROR(VLOOKUP($C53,Embargos!$E$4:$E$3878,1,FALSE), "OK") -> OK | K53: =IF(J53=C53, "EMBARGADO", "LIBERADO") -> LIBERADO
B54: 49 | C54: 21-69 | D54: 21 | E54: 69 | F54: ALBERTO TAVARES PEREIRA | H54: 45392 | I54: AMARELO | J54: =IFERROR(VLOOKUP($C54,Embargos!$E$4:$E$3878,1,FALSE), "OK") -> OK | K54: =IF(J54=C54, "EMBARGADO", "LIBERADO") -> LIBERADO
B55: 50 | C55: 11-47 | D55: 11 | E55: 47 | F55: ALBERTO VIANA MARTINS | H55: 44992 | I55: AMARELO | J55: =IFERROR(VLOOKUP($C55,Embargos!$E$4:$E$3878,1,FALSE), "OK") -> OK | K55: =IF(J55=C55, "EMBARGADO", "LIBERADO") -> LIBERADO
B56: 51 | C56: 29-25 | D56: 29 | E56: 25 | F56: ALCEMIR ROSA PINHEIRO | H56: 44939 | I56: VERMELHO | J56: =IFERROR(VLOOKUP($C56,Embargos!$E$4:$E$3878,1,FALSE), "OK") -> OK | K56: =IF(J56=C56, "EMBARGADO", "LIBERADO") -> LIBERADO
B57: 52 | C57: 21-35 | D57: 21 | E57: 35 | F57: ALCEMIR ROSA PINHEIRO | H57: 45197 | I57: LARANJA | J57: =IFERROR(VLOOKUP($C57,Embargos!$E$4:$E$3878,1,FALSE), "OK") -> OK | K57: =IF(J57=C57, "EMBARGADO", "LIBERADO") -> LIBERADO
... B96: 91 | C96: 4-53 | D96: 4 | E96: 53 | F96: ALLAN LAKISE RAMOS | H96: 45300 | I96: AMARELO | J96: =IFERROR(VLOOKUP($C96,Embargos!$E$4:$E$3878,1,FALSE), "OK") -> OK | K96: =IF(J96=C96, "EMBARGADO", "LIBERADO") -> LIBERADO
B97: 92 | C97: 41-75 | D97: 41 | E97: 75 | F97: ALLOF THAYRO SOUZA PALHANO | G97: SIM | H97: 45199 | I97: ROXO | J97: =IFERROR(VLOOKUP($C97,Embargos!$E$4:$E$3878,1,FALSE), "OK") -> OK | K97: =IF(J97=C97, "EMBARGADO", "LIBERADO") -> LIBERADO
B98: 93 | C98: 9-50 | D98: 9 | E98: 50 | F98: ALLYSON LUIZ DA SILVA DUARTE | H98: 46031 | I98: AMARELO | J98: =IFERROR(VLOOKUP($C98,Embargos!$E$4:$E$3878,1,FALSE), "OK") -> OK | K98: =IF(J98=C98, "EMBARGADO", "LIBERADO") -> LIBERADO
B99: 94 | C99: 37-38 | D99: 37 | E99: 38 | F99: ALMIR RODRIGO PINTO DE OLIVEIRA | H99: 46056 | I99: LARANJA | J99: =IFERROR(VLOOKUP($C99,Embargos!$E$4:$E$3878,1,FALSE), "OK") -> OK | K99: =IF(J99=C99, "EMBARGADO", "LIBERADO") -> LIBERADO
B100: 95 | C100: 31-13 | D100: 31 | E100: 13 | F100: ALMIR SALES RODRIGUES | H100: 45477 | I100: GARDEN | J100: =IFERROR(VLOOKUP($C100,Embargos!$E$4:$E$3878,1,FALSE), "OK") -> OK | K100: =IF(J100=C100, "EMBARGADO", "LIBERADO") -> LIBERADO
B101: 96 | C101: 34-9 | D101: 34 | E101: 9 | F101: ALONSO JUNIOR PINHEIRO CARVALHO | H101: 45257 | I101: GARDEN | J101: =IFERROR(VLOOKUP($C101,Embargos!$E$4:$E$3878,1,FALSE), "OK") -> 34-9 | K101: =IF(J101=C101, "EMBARGADO", "LIBERADO") -> EMBARGADO
B102: 97 | C102: 14-63 | D102: 14 | E102: 63 | F102: ALTERLINE RODRIGUES DA SILVA | H102: 45867 | I102: ROXO | J102: =IFERROR(VLOOKUP($C102,Embargos!$E$4:$E$3878,1,FALSE), "OK") -> OK | K102: =IF(J102=C102, "EMBARGADO", "LIBERADO") -> LIBERADO
B103: 98 | C103: 11-18 | D103: 11 | E103: 18 | F103: ALTINO AYRES DA COSTA JUNIOR | H103: 45978 | I103: EXCLUSIVE | J103: =IFERROR(VLOOKUP($C103,Embargos!$E$4:$E$3878,1,FALSE), "OK") -> 11-18 | K103: =IF(J103=C103, "EMBARGADO", "LIBERADO") -> EMBARGADO
B104: 99 | C104: 22-7 | D104: 22 | E104: 7 | F104: ALUIZIO RODRIGUES DO CARMO FILHO | H104: 45260 | I104: GARDEN | J104: =IFERROR(VLOOKUP($C104,Embargos!$E$4:$E$3878,1,FALSE), "OK") -> OK | K104: =IF(J104=C104, "EMBARGADO", "LIBERADO") -> LIBERADO
B105: 100 | C105: 52-36 | D105: 52 | E105: 36 | F105: ALVARO DALLBELLO | H105: 44949 | I105: LARANJA | J105: =IFERROR(VLOOKUP($C105,Embargos!$E$4:$E$3878,1,FALSE), "OK") -> OK | K105: =IF(J105=C105, "EMBARGADO", "LIBERADO") -> LIBERADO
...

Sheet Embargos
A1: Embargo de obra - 21.10.2026
A2: LOTES BAIRRO ABERTO
A3: SETOR COR | B3: DIAS DE ATRASO | C3: Construção | D3: Habitado | E3: Lote/Quadra | F3: Nome do Cliente | G3: Atraso desde
A4: EXCLUSIVE | B4: 1 | C4: Sem construção | D4: NÃO | E4: 8-19 | F4: ADAM TAVARES MAGALHAES | G4: 20/10/2026
A5: EXCLUSIVE | B5: 1 | C5: Sem construção | D5: NÃO | E5: 29-24 | F5: ADAM TAVARES MAGALHAES | G5: 20/10/2026
A6: GARDEN | B6: 31 | C6: Sem construção | D6: NÃO | E6: 10-10 | F6: ADRIANA BIANCHINI | G6: 20/09/2026
A7: ROXO | B7: 77 | C7: Sem construção | D7: NÃO | E7: 19-62 | F7: ADRIANA DE ALCANTARA SIQUEIRA | G7: 46150
A8: GARDEN | B8: 31 | C8: CASA / RESIDÊNCIA | D8: NÃO | E8: 15-6 | F8: ADRIANA VICTORIA RAAD MARTINS | G8: 46152
A9: LARANJA | B9: 36 | C9: Sem construção | D9: NÃO | E9: 14-72 | F9: AGENOR JOSE DA COSTA NEVES JUNIOR | G9: 15/09/2026
A10: EXCLUSIVE | B10: 93 | C10: Sem construção | D10: NÃO | E10: 13-12 | F10: AGUINALDO LUIZ DOS REIS SILVA JUNIOR | G10: 46150
A11: GARDEN | B11: 1 | C11: Sem construção | D11: NÃO | E11: 22-14 | F11: AIDA MONTEIRO RIBEIRO | G11: 20/10/2026
A12: GARDEN | B12: 16 | C12: Sem construção | D12: NÃO | E12: 37-6 | F12: ALAN MORAES VIANA | G12: 46152
A13: VERMELHO | B13: 11 | C13: Sem construção | D13: NÃO | E13: 52-34 | F13: ALBERTO CEZAR PEREIRA SILVA | G13: 15/10/2026
A14: GARDEN | B14: 36 | C14: Sem construção | D14: NÃO | E14: 4-3 | F14: ALCI COSTA PENA | G14: 15/09/2026
A15: EXCLUSIVE | B15: 31 | C15: Sem construção | D15: NÃO | E15: 39-22 | F15: ALCI COSTA PENA | G15: 20/09/2026
A16: VERMELHO | B16: 36 | C16: Sem construção | D16: NÃO | E16: 5-77 | F16: ALDO LOBO MELO | G16: 15/09/2026
A17: GARDEN | B17: 41 | C17: Sem construção | D17: NÃO | E17: 13-15 | F17: ALESSANDRA SACRAMENTO COSTA | G17: 15/09/2026
A18: ROXO | B18: 11 | C18: Sem construção | D18: NÃO | E18: 23-76 | F18: ALEX DA SILVA MODESTO | G18: 46305
A19: GARDEN | B19: 16 | C19: Sem construção | D19: NÃO | E19: 5-11 | F19: ALEXANDRE PIRES BESSA | G19: 46152
A20: EXCLUSIVE | B20: 62 | C20: Sem construção | D20: NÃO | E20: 9-21 | F20: ALEXANDRE SILVA DE SOUSA | G20: 20/08/2026
A21: AMARELO | B21: 46 | C21: Sem construção | D21: NÃO | E21: 47-69 | F21: ALIANNE LUCIA DE ALMEIDA MATOS | G21: 46151
A22: VERMELHO | B22: 36 | C22: Sem construção | D22: NÃO | E22: 4-54 | F22: ALINE ELLEN FONTES DA COSTA | G22: 20/09/2026
A23: EXCLUSIVE | B23: 72 | C23: Sem construção | D23: NÃO | E23: 3-19 | F23: ALLAN JOSÉ SOUZA SARAIVA | G23: 46303
A24: GARDEN | B24: 46 | C24: Sem construção | D24: NÃO | E24: 34-9 | F24: ALONSO JUNIOR PINHEIRO CARVALHO | G24: 46151
A25: EXCLUSIVE | B25: 41 | C25: Sem construção | D25: NÃO | E25: 11-18 | F25: ALTINO AYRES DA COSTA JUNIOR | G25: 46304
A26: GARDEN | B26: 36 | C26: Sem construção | D26: NÃO | E26: 34-5 | F26: AMANDA FONTELLES ALVES | G26: 15/09/2026
A27: GARDEN | B27: 36 | C27: Sem construção | D27: NÃO | E27: 35-5 | F27: AMANDA FONTELLES ALVES | G27: 15/09/2026
A28: GARDEN | B28: 36 | C28: Sem construção | D28: NÃO | E28: 36-5 | F28: AMANDA FONTELLES ALVES | G28: 15/09/2026
A29: GARDEN | B29: 36 | C29: Sem construção | D29: NÃO | E29: 11-5 | F29: AMANDA FONTELLES ALVES | G29: 15/09/2026
A30: EXCLUSIVE | B30: 46 | C30: Sem construção | D30: NÃO | E30: 24-17 | F30: AMANDA PATRICIA GAUDIO BAYMA | G30: 46151
A31: VERMELHO | B31: 41 | C31: Sem construção | D31: NÃO | E31: 5-26 | F31: AMANDA VITORIA DA SILVA SOUZA | G31: 46304
A32: AMARELO | B32: 16 | C32: Sem construção | D32: NÃO | E32: 28-48 | F32: AMELIA DAS GRAÇAS CANTÃO SIMÕES | G32: 46152
A33: GARDEN | B33: 77 | C33: Sem construção | D33: NÃO | E33: 36-3 | F33: ANA CAROLINA OLIVEIRA FREITAS | G33: 46150
A34: GARDEN | B34: 6 | C34: Sem construção | D34: NÃO | E34: 14-10 | F34: ANA CAROLINA SILVA DE MIRANDA | G34: 15/10/2026
A35: ROXO | B35: 46 | C35: Sem construção | D35: NÃO | E35: 10-57 | F35: ANA CAROLINA SOARES LAUANDE | G35: 46151
A36: GARDEN | B36: 31 | C36: Sem construção | D36: NÃO | E36: 15-12 | F36: ANA CLAUDIA WANZELER MARCAL CARVALHO | G36: 20/09/2026
A37: VERMELHO | B37: 98 | C37: Sem construção | D37: NÃO | E37: 27-42 | F37: ANA PAULA RODRIGUES LOUREIRO | G37: 20/07/2026
A38: LARANJA | B38: 31 | C38: Sem construção | D38: NÃO | E38: 17-45 | F38: ANA PAULA SILVA DOS SANTOS | G38: 20/09/2026
A39: GARDEN | B39: 6 | C39: Sem construção | D39: NÃO | E39: 24-15 | F39: ANA QUEZIA AIRES ARAUJO | G39: 15/10/2026
A40: EXCLUSIVE | B40: 154 | C40: Sem construção | D40: NÃO | E40: 30-18 | F40: ANA TATIANE COELHO REBELO | G40: 20/05/2026
...
